ERROR:root:get_elo.py: 'Rank' - Error occurred at line 3805
ERROR:root:get_elo.py: get_normalized_ranks() takes 1 positional argument but 2 were given - Error occurred at line 241
ERROR:root:get_elo.py: name 'this_week' is not defined - Error occurred at line 160
ERROR:root:get_elo.py: name 'get_elo_week' is not defined - Error occurred at line 162
ERROR:root:get_elo.py: name 'week_3_df' is not defined - Error occurred at line 122
ERROR:root:get_elo.py: 'list' object has no attribute 'between' - Error occurred at line 31
ERROR:root:get_elo.py: cannot access local variable 'week' where it is not associated with a value - Error occurred at line 174
ERROR:root:get_elo.py: You are trying to merge on int64 and object columns. If you wish to proceed you should use pd.concat - Error occurred at line 1340
ERROR:root:get_elo.py: You are trying to merge on object and int64 columns. If you wish to proceed you should use pd.concat - Error occurred at line 1340
ERROR:root:get_elo.py: name 'elo_week' is not defined - Error occurred at line 188
ERROR:root:get_elo.py: name 'power_ranks_season_trend' is not defined - Error occurred at line 186
ERROR:root:get_elo.py: name 'week_df' is not defined - Error occurred at line 143
ERROR:root:get_elo.py: expected_outcome() takes 2 positional arguments but 3 were given - Error occurred at line 192
ERROR:root:get_elo.py: You are trying to merge on int64 and object columns. If you wish to proceed you should use pd.concat - Error occurred at line 1340
ERROR:root:get_elo.py: You are trying to merge on int64 and object columns. If you wish to proceed you should use pd.concat - Error occurred at line 1340
ERROR:root:get_elo.py: unhashable type: 'Series' - Error occurred at line 5857
ERROR:root:get_elo.py: unhashable type: 'Series' - Error occurred at line 5857
ERROR:root:get_elo.py: unhashable type: 'Series' - Error occurred at line 5857
ERROR:root:get_elo.py: unhashable type: 'Series' - Error occurred at line 5857
ERROR:root:get_elo.py: unhashable type: 'Series' - Error occurred at line 5857
ERROR:root:get_elo.py: unhashable type: 'Series' - Error occurred at line 5857
ERROR:root:get_elo.py: cannot access local variable 'merged_df' where it is not associated with a value - Error occurred at line 116
ERROR:root:get_elo.py: unhashable type: 'Series' - Error occurred at line 5857
ERROR:root:get_elo.py: unhashable type: 'Series' - Error occurred at line 5857
ERROR:root:get_elo.py: 'DataFrame' object has no attribute 'to_frame' - Error occurred at line 5902
ERROR:root:get_elo.py: unhashable type: 'Series' - Error occurred at line 5857
ERROR:root:get_elo.py: 'DataFrame' object has no attribute 'to_frame' - Error occurred at line 5902
ERROR:root:get_elo.py: name 'running_elo' is not defined - Error occurred at line 212
ERROR:root:get_elo.py: 'DataFrame' object has no attribute 'joined_df' - Error occurred at line 5902
ERROR:root:get_elo.py: unhashable type: 'Series' - Error occurred at line 5857
ERROR:root:get_elo.py: You are trying to merge on object and int32 columns. If you wish to proceed you should use pd.concat - Error occurred at line 1340
ERROR:root:get_elo.py: setting an array element with a sequence. - Error occurred at line 170
ERROR:root:get_elo.py: You are trying to merge on object and int32 columns. If you wish to proceed you should use pd.concat - Error occurred at line 1340
ERROR:root:get_elo.py: unhashable type: 'Series' - Error occurred at line 5857
ERROR:root:get_elo.py: setting an array element with a sequence. - Error occurred at line 170
ERROR:root:get_elo.py: setting an array element with a sequence. - Error occurred at line 170
ERROR:root:get_elo.py: unhashable type: 'Series' - Error occurred at line 5857
ERROR:root:get_elo.py: unhashable type: 'Series' - Error occurred at line 5857
ERROR:root:get_elo.py: setting an array element with a sequence. - Error occurred at line 170
ERROR:root:get_elo.py: setting an array element with a sequence. - Error occurred at line 170
ERROR:root:get_elo.py: setting an array element with a sequence. - Error occurred at line 170
ERROR:root:get_elo.py: setting an array element with a sequence. - Error occurred at line 170
ERROR:root:get_elo.py: setting an array element with a sequence. - Error occurred at line 170
ERROR:root:get_elo.py: unhashable type: 'Series' - Error occurred at line 5857
ERROR:root:get_elo.py: cannot access local variable 'week' where it is not associated with a value - Error occurred at line 95
ERROR:root:get_elo.py: cannot access local variable 'week' where it is not associated with a value - Error occurred at line 95
ERROR:root:get_elo.py: unhashable type: 'Series' - Error occurred at line 5857
ERROR:root:get_elo.py: 'Team_Number' - Error occurred at line 1850
ERROR:root:get_elo.py: The column label 'Team_Number' is not unique. - Error occurred at line 1865
ERROR:root:get_elo.py: The column label 'Team_Number' is not unique. - Error occurred at line 1865
ERROR:root:get_elo.py: The column label 'Team_Number' is not unique. - Error occurred at line 1865
ERROR:root:get_elo.py: 'Team_Number' - Error occurred at line 1850
ERROR:root:get_elo.py: The column label 'Team_Number' is not unique. - Error occurred at line 1865
ERROR:root:get_elo.py: 'Team_Number' - Error occurred at line 1850
ERROR:root:get_elo.py: "['Team_Num'] not in index" - Error occurred at line 6174
ERROR:root:get_elo.py: 'Team_Num' - Error occurred at line 1850
ERROR:root:get_elo.py: 'Team_Num' - Error occurred at line 1850
ERROR:root:get_elo.py: 'Team_Num' - Error occurred at line 1850
ERROR:root:get_elo.py: The column label 'Team_Number' is not unique. - Error occurred at line 1865
ERROR:root:get_elo.py: 'Opponent_Team_Number' - Error occurred at line 3805
ERROR:root:get_elo.py: The column label 'Team_Number' is not unique. - Error occurred at line 1865
ERROR:root:get_elo.py: You are trying to merge on int64 and object columns. If you wish to proceed you should use pd.concat - Error occurred at line 1340
ERROR:root:get_elo.py: You are trying to merge on int64 and object columns. If you wish to proceed you should use pd.concat - Error occurred at line 1340
ERROR:root:get_elo.py: You are trying to merge on int64 and object columns. If you wish to proceed you should use pd.concat - Error occurred at line 1340
ERROR:root:get_elo.py: name 'running_elo' is not defined - Error occurred at line 214
ERROR:root:get_elo.py: list.append() takes no keyword arguments - Error occurred at line 215
ERROR:root:get_elo.py: "['ELO_Sum'] not in index" - Error occurred at line 6174
ERROR:root:get_elo.py: "['ELO_Sum'] not in index" - Error occurred at line 6174
ERROR:root:get_elo.py: "['ELO_Sum'] not in index" - Error occurred at line 6174
ERROR:root:get_elo.py: "['ELO_Team_Sum'] not in index" - Error occurred at line 6174
ERROR:root:get_elo.py: "['ELO_Team_Sum'] not in index" - Error occurred at line 6174
ERROR:root:get_elo.py: name 'df' is not defined - Error occurred at line 53
ERROR:root:get_elo.py: name 'expected_result_ra' is not defined - Error occurred at line 139
ERROR:root:get_elo.py: name 'np' is not defined - Error occurred at line 120
ERROR:root:get_elo.py: "None of [Index(['Opponent_Team_Number', 'Week'], dtype='object')] are in the [columns]" - Error occurred at line 6171
ERROR:root:get_elo.py: "None of [Index(['Opponent_Team_Number', 'Week'], dtype='object')] are in the [columns]" - Error occurred at line 6171
ERROR:root:get_elo.py: documents must be a non-empty list - Error occurred at line 691
ERROR:root:get_elo.py: name 'scaled_atual' is not defined - Error occurred at line 143
ERROR:root:get_elo.py: name 'scaled_actual' is not defined - Error occurred at line 143
ERROR:root:get_elo.py: documents must be a non-empty list - Error occurred at line 691
ERROR:root:get_elo.py: documents must be a non-empty list - Error occurred at line 691
ERROR:root:get_elo.py: documents must be a non-empty list - Error occurred at line 691
ERROR:root:get_elo.py: documents must be a non-empty list - Error occurred at line 691
ERROR:root:get_elo.py: 'TEAM_NUM' - Error occurred at line 1850
ERROR:root:get_elo.py: 'TEAM_NUM' - Error occurred at line 1850
ERROR:root:get_elo.py: documents must be a non-empty list - Error occurred at line 691
ERROR:root:get_elo.py: documents must be a non-empty list - Error occurred at line 691
ERROR:root:get_elo.py: "None of [Index(['Opponent_Team_Number', 'Week'], dtype='object')] are in the [columns]" - Error occurred at line 6171
ERROR:root:get_elo.py: name 'expected_outcome_df' is not defined - Error occurred at line 222
ERROR:root:get_elo.py: "['Expected_Result_Ra', 'Normalized_Score_Difference'] not found in axis" - Error occurred at line 6975
ERROR:root:get_elo.py: "['Expected_Result_Ra', 'Normalized_Score_Difference'] not found in axis" - Error occurred at line 6975
ERROR:root:get_elo.py: documents must be a non-empty list - Error occurred at line 691
ERROR:root:get_elo.py: "None of [Index(['Opponent_Team_Number', 'Week'], dtype='object')] are in the [columns]" - Error occurred at line 6171
ERROR:root:get_elo.py: "None of [Index(['Opponent_Team_Number', 'Week'], dtype='object')] are in the [columns]" - Error occurred at line 6171
ERROR:root:get_elo.py: "None of [Index(['Opponent_Team_Number', 'Week'], dtype='object')] are in the [columns]" - Error occurred at line 6171
ERROR:root:get_elo.py: "None of [Index(['Opponent_Team_Number', 'Week'], dtype='object')] are in the [columns]" - Error occurred at line 6171
ERROR:root:get_elo.py: 'Team_Number' - Error occurred at line 3805
ERROR:root:get_elo.py: 'Team_Number' - Error occurred at line 3805
ERROR:root:get_elo.py: name 'k_factor_steps' is not defined - Error occurred at line 124
ERROR:root:get_elo.py: name 'df' is not defined - Error occurred at line 123
ERROR:root:get_elo.py: cannot access local variable 'appended_df' where it is not associated with a value - Error occurred at line 150
ERROR:root:get_elo.py: 'Expected_Result_Ra_Transformed' - Error occurred at line 3805
ERROR:root:get_elo.py: cannot access local variable 'appended_df' where it is not associated with a value - Error occurred at line 146
ERROR:root:get_elo.py: cannot access local variable 'appended_df' where it is not associated with a value - Error occurred at line 147
ERROR:root:get_elo.py: cannot access local variable 'appended_df' where it is not associated with a value - Error occurred at line 148
ERROR:root:get_elo.py: cannot access local variable 'appended_df' where it is not associated with a value - Error occurred at line 150
ERROR:root:get_elo.py: 'Team_Number' - Error occurred at line 3805
ERROR:root:get_elo.py: unsupported operand type(s) for +: 'function' and 'int' - Error occurred at line 161
ERROR:root:get_remaining_sos.py: documents must be a non-empty list - Error occurred at line 691
ERROR:root:get_remaining_sos.py: documents must be a non-empty list - Error occurred at line 691
ERROR:root:get_remaining_sos.py: documents must be a non-empty list - Error occurred at line 691
ERROR:root:get_remaining_sos.py: 'Team' - Error occurred at line 3805
ERROR:root:get_elo.py: "['ELO_Team_Sum'] not in index" - Line 6252
ERROR:root:get_elo.py: "['ELO_Team_Sum'] not in index" - Line 6252
ERROR:root:get_elo.py: "['ELO_Team_Sum'] not in index" - Line 6252
ERROR:root:get_elo.py: "['ELO_Team_Sum'] not in index" - Line 6174
ERROR:root:get_remaining_sos.py: 'Avg_Power_Rank' - Error occurred at line 3805
ERROR:root:get_remaining_sos.py: 'Week' - Error occurred at line 3805
ERROR:root:get_remaining_sos.py: 'Opponent_Team_Number' - Error occurred at line 1850
ERROR:root:get_remaining_sos.py: 'Week' - Error occurred at line 3805
ERROR:root:get_remaining_sos.py: 'Team_Number' - Error occurred at line 888
ERROR:root:get_remaining_sos.py: 'Team_Number' - Error occurred at line 888
